$ python clia.py
CLIA>>>
Traceback (most recent call last):
  File "C:\Users\user\Documents\personal_projects\CLIA\clia.py", line 93, in <module>
    interactiveMode()
  File "C:\Users\user\Documents\personal_projects\CLIA\clia.py", line 80, in interactiveMode
    response = palm.generate_text(
               ^^^^^^^^^^^^^^^^^^^
  File "C:\Users\user\AppData\Local\Programs\Python\Python311\Lib\site-packages\google\generativeai\text.py", line 200, in generate_text
    return _generate_response(client=client, request=request)
           ^^^^^^^^^^^^^^^^^^^^^^^^^^^^^^^^^^^^^^^^^^^^^^^^^^
  File "C:\Users\user\AppData\Local\Programs\Python\Python311\Lib\site-packages\google\generativeai\text.py", line 232, in _generate_response
    response = client.generate_text(request)
               ^^^^^^^^^^^^^^^^^^^^^^^^^^^^^
  File "C:\Users\user\AppData\Local\Programs\Python\Python311\Lib\site-packages\google\ai\generativelanguage_v1beta\services\text_service\client.py", line 648, in generate_text
    response = rpc(
               ^^^^
  File "C:\Users\user\AppData\Local\Programs\Python\Python311\Lib\site-packages\google\api_core\gapic_v1\method.py", line 131, in __call__
    return wrapped_func(*args, **kwargs)
           ^^^^^^^^^^^^^^^^^^^^^^^^^^^^^
  File "C:\Users\user\AppData\Local\Programs\Python\Python311\Lib\site-packages\google\api_core\retry\retry_unary.py", line 293, in retry_wrapped_func
    return retry_target(
           ^^^^^^^^^^^^^
  File "C:\Users\user\AppData\Local\Programs\Python\Python311\Lib\site-packages\google\api_core\retry\retry_unary.py", line 153, in retry_target
    _retry_error_helper(
  File "C:\Users\user\AppData\Local\Programs\Python\Python311\Lib\site-packages\google\api_core\retry\retry_base.py", line 212, in _retry_error_helper
    raise final_exc from source_exc
  File "C:\Users\user\AppData\Local\Programs\Python\Python311\Lib\site-packages\google\api_core\retry\retry_unary.py", line 144, in retry_target
    result = target()
             ^^^^^^^^
  File "C:\Users\user\AppData\Local\Programs\Python\Python311\Lib\site-packages\google\api_core\timeout.py", line 120, in func_with_timeout
    return func(*args, **kwargs)
           ^^^^^^^^^^^^^^^^^^^^^
  File "C:\Users\user\AppData\Local\Programs\Python\Python311\Lib\site-packages\google\api_core\grpc_helpers.py", line 81, in error_remapped_callable
    raise exceptions.from_grpc_error(exc) from exc
google.api_core.exceptions.InvalidArgument: 400 * GenerateTextRequest.prompt.text: prompt text is not specified
